2020-05-14 00:39:49,958 ERROR: Exception on / [GET] [in C:\Users\s2905\Desktop\EA Project\abc\venv\lib\site-packages\flask\app.py:1891]
Traceback (most recent call last):
  File "C:\Users\s2905\Desktop\EA Project\abc\venv\lib\site-packages\flask\app.py", line 2447, in wsgi_app
    response = self.full_dispatch_request()
  File "C:\Users\s2905\Desktop\EA Project\abc\venv\lib\site-packages\flask\app.py", line 1952, in full_dispatch_request
    rv = self.handle_user_exception(e)
  File "C:\Users\s2905\Desktop\EA Project\abc\venv\lib\site-packages\flask\app.py", line 1821, in handle_user_exception
    reraise(exc_type, exc_value, tb)
  File "C:\Users\s2905\Desktop\EA Project\abc\venv\lib\site-packages\flask\_compat.py", line 39, in reraise
    raise value
  File "C:\Users\s2905\Desktop\EA Project\abc\venv\lib\site-packages\flask\app.py", line 1950, in full_dispatch_request
    rv = self.dispatch_request()
  File "C:\Users\s2905\Desktop\EA Project\abc\venv\lib\site-packages\flask\app.py", line 1936, in dispatch_request
    return self.view_functions[rule.endpoint](**req.view_args)
  File "C:\Users\s2905\Desktop\EA Project\abc\app\main\routes.py", line 27, in ez
    if tech.picture_name and techv2.picture_name == "":
AttributeError: 'BaseQuery' object has no attribute 'picture_name'
2020-05-14 00:42:28,261 INFO: Microblog startup [in C:\Users\s2905\Desktop\EA Project\abc\app\__init__.py:74]
2020-05-14 00:42:29,494 ERROR: Exception on / [GET] [in C:\Users\s2905\Desktop\EA Project\abc\venv\lib\site-packages\flask\app.py:1891]
Traceback (most recent call last):
  File "C:\Users\s2905\Desktop\EA Project\abc\venv\lib\site-packages\flask\app.py", line 2447, in wsgi_app
    response = self.full_dispatch_request()
  File "C:\Users\s2905\Desktop\EA Project\abc\venv\lib\site-packages\flask\app.py", line 1952, in full_dispatch_request
    rv = self.handle_user_exception(e)
  File "C:\Users\s2905\Desktop\EA Project\abc\venv\lib\site-packages\flask\app.py", line 1821, in handle_user_exception
    reraise(exc_type, exc_value, tb)
  File "C:\Users\s2905\Desktop\EA Project\abc\venv\lib\site-packages\flask\_compat.py", line 39, in reraise
    raise value
  File "C:\Users\s2905\Desktop\EA Project\abc\venv\lib\site-packages\flask\app.py", line 1950, in full_dispatch_request
    rv = self.dispatch_request()
  File "C:\Users\s2905\Desktop\EA Project\abc\venv\lib\site-packages\flask\app.py", line 1936, in dispatch_request
    return self.view_functions[rule.endpoint](**req.view_args)
  File "C:\Users\s2905\Desktop\EA Project\abc\app\main\routes.py", line 28, in ez
    print(tech[key])
  File "C:\Users\s2905\Desktop\EA Project\abc\venv\lib\site-packages\sqlalchemy\orm\query.py", line 3083, in __getitem__
    return list(self[item : item + 1])[0]
TypeError: unsupported operand type(s) for +: 'Tech' and 'int'
2020-05-14 02:06:16,652 INFO: Microblog startup [in C:\Users\s2905\Desktop\EA Project\abc\app\__init__.py:74]
2020-05-14 02:06:18,062 ERROR: Exception on / [GET] [in C:\Users\s2905\Desktop\EA Project\abc\venv\lib\site-packages\flask\app.py:1891]
Traceback (most recent call last):
  File "C:\Users\s2905\Desktop\EA Project\abc\venv\lib\site-packages\flask\app.py", line 2447, in wsgi_app
    response = self.full_dispatch_request()
  File "C:\Users\s2905\Desktop\EA Project\abc\venv\lib\site-packages\flask\app.py", line 1952, in full_dispatch_request
    rv = self.handle_user_exception(e)
  File "C:\Users\s2905\Desktop\EA Project\abc\venv\lib\site-packages\flask\app.py", line 1821, in handle_user_exception
    reraise(exc_type, exc_value, tb)
  File "C:\Users\s2905\Desktop\EA Project\abc\venv\lib\site-packages\flask\_compat.py", line 39, in reraise
    raise value
  File "C:\Users\s2905\Desktop\EA Project\abc\venv\lib\site-packages\flask\app.py", line 1950, in full_dispatch_request
    rv = self.dispatch_request()
  File "C:\Users\s2905\Desktop\EA Project\abc\venv\lib\site-packages\flask\app.py", line 1936, in dispatch_request
    return self.view_functions[rule.endpoint](**req.view_args)
  File "C:\Users\s2905\Desktop\EA Project\abc\app\main\routes.py", line 27, in ez
    print(tech["picture_name"])
  File "C:\Users\s2905\Desktop\EA Project\abc\venv\lib\site-packages\sqlalchemy\orm\query.py", line 3083, in __getitem__
    return list(self[item : item + 1])[0]
TypeError: can only concatenate str (not "int") to str
2020-05-14 02:08:40,523 INFO: Microblog startup [in C:\Users\s2905\Desktop\EA Project\abc\app\__init__.py:74]
2020-05-14 02:08:41,735 ERROR: Exception on / [GET] [in C:\Users\s2905\Desktop\EA Project\abc\venv\lib\site-packages\flask\app.py:1891]
Traceback (most recent call last):
  File "C:\Users\s2905\Desktop\EA Project\abc\venv\lib\site-packages\flask\app.py", line 2447, in wsgi_app
    response = self.full_dispatch_request()
  File "C:\Users\s2905\Desktop\EA Project\abc\venv\lib\site-packages\flask\app.py", line 1952, in full_dispatch_request
    rv = self.handle_user_exception(e)
  File "C:\Users\s2905\Desktop\EA Project\abc\venv\lib\site-packages\flask\app.py", line 1821, in handle_user_exception
    reraise(exc_type, exc_value, tb)
  File "C:\Users\s2905\Desktop\EA Project\abc\venv\lib\site-packages\flask\_compat.py", line 39, in reraise
    raise value
  File "C:\Users\s2905\Desktop\EA Project\abc\venv\lib\site-packages\flask\app.py", line 1950, in full_dispatch_request
    rv = self.dispatch_request()
  File "C:\Users\s2905\Desktop\EA Project\abc\venv\lib\site-packages\flask\app.py", line 1936, in dispatch_request
    return self.view_functions[rule.endpoint](**req.view_args)
  File "C:\Users\s2905\Desktop\EA Project\abc\app\main\routes.py", line 27, in ez
    print(str(tech["picture_name"]))
  File "C:\Users\s2905\Desktop\EA Project\abc\venv\lib\site-packages\sqlalchemy\orm\query.py", line 3083, in __getitem__
    return list(self[item : item + 1])[0]
TypeError: can only concatenate str (not "int") to str
2020-05-14 02:09:25,754 INFO: Microblog startup [in C:\Users\s2905\Desktop\EA Project\abc\app\__init__.py:74]
2020-05-14 02:09:26,827 ERROR: Exception on / [GET] [in C:\Users\s2905\Desktop\EA Project\abc\venv\lib\site-packages\flask\app.py:1891]
Traceback (most recent call last):
  File "C:\Users\s2905\Desktop\EA Project\abc\venv\lib\site-packages\flask\app.py", line 2447, in wsgi_app
    response = self.full_dispatch_request()
  File "C:\Users\s2905\Desktop\EA Project\abc\venv\lib\site-packages\flask\app.py", line 1952, in full_dispatch_request
    rv = self.handle_user_exception(e)
  File "C:\Users\s2905\Desktop\EA Project\abc\venv\lib\site-packages\flask\app.py", line 1821, in handle_user_exception
    reraise(exc_type, exc_value, tb)
  File "C:\Users\s2905\Desktop\EA Project\abc\venv\lib\site-packages\flask\_compat.py", line 39, in reraise
    raise value
  File "C:\Users\s2905\Desktop\EA Project\abc\venv\lib\site-packages\flask\app.py", line 1950, in full_dispatch_request
    rv = self.dispatch_request()
  File "C:\Users\s2905\Desktop\EA Project\abc\venv\lib\site-packages\flask\app.py", line 1936, in dispatch_request
    return self.view_functions[rule.endpoint](**req.view_args)
  File "C:\Users\s2905\Desktop\EA Project\abc\app\main\routes.py", line 27, in ez
    print(str(tech["picture_name"]))
  File "C:\Users\s2905\Desktop\EA Project\abc\venv\lib\site-packages\sqlalchemy\orm\query.py", line 3083, in __getitem__
    return list(self[item : item + 1])[0]
TypeError: can only concatenate str (not "int") to str
2020-05-14 02:10:08,833 INFO: Microblog startup [in C:\Users\s2905\Desktop\EA Project\abc\app\__init__.py:74]
2020-05-14 02:12:00,771 INFO: Microblog startup [in C:\Users\s2905\Desktop\EA Project\abc\app\__init__.py:74]
2020-05-14 02:12:02,272 ERROR: Exception on / [GET] [in C:\Users\s2905\Desktop\EA Project\abc\venv\lib\site-packages\flask\app.py:1891]
Traceback (most recent call last):
  File "C:\Users\s2905\Desktop\EA Project\abc\venv\lib\site-packages\flask\app.py", line 2447, in wsgi_app
    response = self.full_dispatch_request()
  File "C:\Users\s2905\Desktop\EA Project\abc\venv\lib\site-packages\flask\app.py", line 1952, in full_dispatch_request
    rv = self.handle_user_exception(e)
  File "C:\Users\s2905\Desktop\EA Project\abc\venv\lib\site-packages\flask\app.py", line 1821, in handle_user_exception
    reraise(exc_type, exc_value, tb)
  File "C:\Users\s2905\Desktop\EA Project\abc\venv\lib\site-packages\flask\_compat.py", line 39, in reraise
    raise value
  File "C:\Users\s2905\Desktop\EA Project\abc\venv\lib\site-packages\flask\app.py", line 1950, in full_dispatch_request
    rv = self.dispatch_request()
  File "C:\Users\s2905\Desktop\EA Project\abc\venv\lib\site-packages\flask\app.py", line 1936, in dispatch_request
    return self.view_functions[rule.endpoint](**req.view_args)
  File "C:\Users\s2905\Desktop\EA Project\abc\app\main\routes.py", line 25, in ez
    techv2 = Tech.query.order_by(func.random()).limit(2) - tech
TypeError: unsupported operand type(s) for -: 'BaseQuery' and 'BaseQuery'
2020-05-14 02:12:23,460 INFO: Microblog startup [in C:\Users\s2905\Desktop\EA Project\abc\app\__init__.py:74]
