2020-05-13 19:55:40,444 INFO: Microblog startup [in C:\Users\s2905\Desktop\EA Project\abc\app\__init__.py:74]
2020-05-13 22:01:03,089 INFO: Microblog startup [in C:\Users\s2905\Desktop\EA Project\abc\app\__init__.py:74]
2020-05-13 22:04:18,295 INFO: Microblog startup [in C:\Users\s2905\Desktop\EA Project\abc\app\__init__.py:74]
2020-05-13 22:08:34,375 INFO: Microblog startup [in C:\Users\s2905\Desktop\EA Project\abc\app\__init__.py:74]
2020-05-13 22:13:00,518 INFO: Microblog startup [in C:\Users\s2905\Desktop\EA Project\abc\app\__init__.py:74]
2020-05-13 22:17:47,665 INFO: Microblog startup [in C:\Users\s2905\Desktop\EA Project\abc\app\__init__.py:74]
2020-05-13 22:22:24,611 INFO: Microblog startup [in C:\Users\s2905\Desktop\EA Project\abc\app\__init__.py:74]
2020-05-13 22:29:22,267 INFO: Microblog startup [in C:\Users\s2905\Desktop\EA Project\abc\app\__init__.py:74]
2020-05-13 22:29:55,220 INFO: Microblog startup [in C:\Users\s2905\Desktop\EA Project\abc\app\__init__.py:74]
2020-05-13 22:31:18,961 INFO: Microblog startup [in C:\Users\s2905\Desktop\EA Project\abc\app\__init__.py:74]
2020-05-13 22:35:03,845 INFO: Microblog startup [in C:\Users\s2905\Desktop\EA Project\abc\app\__init__.py:74]
2020-05-13 22:35:05,113 ERROR: Exception on / [GET] [in C:\Users\s2905\Desktop\EA Project\abc\venv\lib\site-packages\flask\app.py:1891]
Traceback (most recent call last):
  File "C:\Users\s2905\Desktop\EA Project\abc\venv\lib\site-packages\sqlalchemy\engine\base.py", line 1247, in _execute_context
    self.dialect.do_execute(
  File "C:\Users\s2905\Desktop\EA Project\abc\venv\lib\site-packages\sqlalchemy\engine\default.py", line 590, in do_execute
    cursor.execute(statement, parameters)
sqlite3.OperationalError: row value misused

The above exception was the direct cause of the following exception:

Traceback (most recent call last):
  File "C:\Users\s2905\Desktop\EA Project\abc\venv\lib\site-packages\flask\app.py", line 2447, in wsgi_app
    response = self.full_dispatch_request()
  File "C:\Users\s2905\Desktop\EA Project\abc\venv\lib\site-packages\flask\app.py", line 1952, in full_dispatch_request
    rv = self.handle_user_exception(e)
  File "C:\Users\s2905\Desktop\EA Project\abc\venv\lib\site-packages\flask\app.py", line 1821, in handle_user_exception
    reraise(exc_type, exc_value, tb)
  File "C:\Users\s2905\Desktop\EA Project\abc\venv\lib\site-packages\flask\_compat.py", line 39, in reraise
    raise value
  File "C:\Users\s2905\Desktop\EA Project\abc\venv\lib\site-packages\flask\app.py", line 1950, in full_dispatch_request
    rv = self.dispatch_request()
  File "C:\Users\s2905\Desktop\EA Project\abc\venv\lib\site-packages\flask\app.py", line 1936, in dispatch_request
    return self.view_functions[rule.endpoint](**req.view_args)
  File "C:\Users\s2905\Desktop\EA Project\abc\app\main\routes.py", line 31, in ez
    return render_template('ez.html', title=_('E-Zone'), all=all, tech=tech, techv2=techv2, hot=hot, network=network,
  File "C:\Users\s2905\Desktop\EA Project\abc\venv\lib\site-packages\flask\templating.py", line 137, in render_template
    return _render(
  File "C:\Users\s2905\Desktop\EA Project\abc\venv\lib\site-packages\flask\templating.py", line 120, in _render
    rv = template.render(context)
  File "C:\Users\s2905\Desktop\EA Project\abc\venv\lib\site-packages\jinja2\environment.py", line 1090, in render
    self.environment.handle_exception()
  File "C:\Users\s2905\Desktop\EA Project\abc\venv\lib\site-packages\jinja2\environment.py", line 832, in handle_exception
    reraise(*rewrite_traceback_stack(source=source))
  File "C:\Users\s2905\Desktop\EA Project\abc\venv\lib\site-packages\jinja2\_compat.py", line 28, in reraise
    raise value.with_traceback(tb)
  File "C:\Users\s2905\Desktop\EA Project\abc\app\templates\ez.html", line 1, in top-level template code
    {% extends "base.html" %}
  File "C:\Users\s2905\Desktop\EA Project\abc\app\templates\base.html", line 1, in top-level template code
    {% extends 'bootstrap/base.html' %}
  File "C:\Users\s2905\Desktop\EA Project\abc\venv\lib\site-packages\flask_bootstrap\templates\bootstrap\base.html", line 1, in top-level template code
    {% block doc -%}
  File "C:\Users\s2905\Desktop\EA Project\abc\venv\lib\site-packages\flask_bootstrap\templates\bootstrap\base.html", line 4, in block "doc"
    {%- block html %}
  File "C:\Users\s2905\Desktop\EA Project\abc\venv\lib\site-packages\flask_bootstrap\templates\bootstrap\base.html", line 20, in block "html"
    {% block body -%}
  File "C:\Users\s2905\Desktop\EA Project\abc\venv\lib\site-packages\flask_bootstrap\templates\bootstrap\base.html", line 23, in block "body"
    {% block content -%}
  File "C:\Users\s2905\Desktop\EA Project\abc\app\templates\base.html", line 98, in block "content"
    {% block current_app_content %}{% endblock %}
  File "C:\Users\s2905\Desktop\EA Project\abc\app\templates\ez.html", line 60, in block "current_app_content"
    {% for news in techv2 %}
  File "C:\Users\s2905\Desktop\EA Project\abc\venv\lib\site-packages\sqlalchemy\orm\query.py", line 3405, in __iter__
    return self._execute_and_instances(context)
  File "C:\Users\s2905\Desktop\EA Project\abc\venv\lib\site-packages\sqlalchemy\orm\query.py", line 3430, in _execute_and_instances
    result = conn.execute(querycontext.statement, self._params)
  File "C:\Users\s2905\Desktop\EA Project\abc\venv\lib\site-packages\sqlalchemy\engine\base.py", line 984, in execute
    return meth(self, multiparams, params)
  File "C:\Users\s2905\Desktop\EA Project\abc\venv\lib\site-packages\sqlalchemy\sql\elements.py", line 293, in _execute_on_connection
    return connection._execute_clauseelement(self, multiparams, params)
  File "C:\Users\s2905\Desktop\EA Project\abc\venv\lib\site-packages\sqlalchemy\engine\base.py", line 1097, in _execute_clauseelement
    ret = self._execute_context(
  File "C:\Users\s2905\Desktop\EA Project\abc\venv\lib\site-packages\sqlalchemy\engine\base.py", line 1287, in _execute_context
    self._handle_dbapi_exception(
  File "C:\Users\s2905\Desktop\EA Project\abc\venv\lib\site-packages\sqlalchemy\engine\base.py", line 1481, in _handle_dbapi_exception
    util.raise_(
  File "C:\Users\s2905\Desktop\EA Project\abc\venv\lib\site-packages\sqlalchemy\util\compat.py", line 178, in raise_
    raise exception
  File "C:\Users\s2905\Desktop\EA Project\abc\venv\lib\site-packages\sqlalchemy\engine\base.py", line 1247, in _execute_context
    self.dialect.do_execute(
  File "C:\Users\s2905\Desktop\EA Project\abc\venv\lib\site-packages\sqlalchemy\engine\default.py", line 590, in do_execute
    cursor.execute(statement, parameters)
sqlalchemy.exc.OperationalError: (sqlite3.OperationalError) row value misused
[SQL: SELECT tech.id AS tech_id, tech.picture_name AS tech_picture_name, tech.st_cat AS tech_st_cat, tech.nd_cat AS tech_nd_cat 
FROM tech 
WHERE tech.picture_name != (SELECT tech.id AS tech_id, tech.picture_name AS tech_picture_name, tech.st_cat AS tech_st_cat, tech.nd_cat AS tech_nd_cat 
FROM tech ORDER BY random()
 LIMIT ? OFFSET ?) ORDER BY random()
 LIMIT ? OFFSET ?]
[parameters: (2, 0, 2, 0)]
(Background on this error at: http://sqlalche.me/e/e3q8)
2020-05-13 22:37:35,790 INFO: Microblog startup [in C:\Users\s2905\Desktop\EA Project\abc\app\__init__.py:74]
