2020-03-19 04:57:56,749 ERROR: Exception on /user/1234 [GET] [in /home/osboxes/PycharmProjects/microblog/venv/lib/python3.6/site-packages/flask/app.py:1891]
Traceback (most recent call last):
  File "/home/osboxes/PycharmProjects/microblog/venv/lib/python3.6/site-packages/flask/app.py", line 2446, in wsgi_app
    response = self.full_dispatch_request()
  File "/home/osboxes/PycharmProjects/microblog/venv/lib/python3.6/site-packages/flask/app.py", line 1951, in full_dispatch_request
    rv = self.handle_user_exception(e)
  File "/home/osboxes/PycharmProjects/microblog/venv/lib/python3.6/site-packages/flask/app.py", line 1820, in handle_user_exception
    reraise(exc_type, exc_value, tb)
  File "/home/osboxes/PycharmProjects/microblog/venv/lib/python3.6/site-packages/flask/_compat.py", line 39, in reraise
    raise value
  File "/home/osboxes/PycharmProjects/microblog/venv/lib/python3.6/site-packages/flask/app.py", line 1949, in full_dispatch_request
    rv = self.dispatch_request()
  File "/home/osboxes/PycharmProjects/microblog/venv/lib/python3.6/site-packages/flask/app.py", line 1935, in dispatch_request
    return self.view_functions[rule.endpoint](**req.view_args)
  File "/home/osboxes/PycharmProjects/microblog/venv/lib/python3.6/site-packages/flask_login/utils.py", line 272, in decorated_view
    return func(*args, **kwargs)
  File "/home/osboxes/PycharmProjects/microblog/app/routes.py", line 81, in user
    return render_template('user.html', user=user, posts=posts)
  File "/home/osboxes/PycharmProjects/microblog/venv/lib/python3.6/site-packages/flask/templating.py", line 140, in render_template
    ctx.app,
  File "/home/osboxes/PycharmProjects/microblog/venv/lib/python3.6/site-packages/flask/templating.py", line 120, in _render
    rv = template.render(context)
  File "/home/osboxes/PycharmProjects/microblog/venv/lib/python3.6/site-packages/jinja2/environment.py", line 1090, in render
    self.environment.handle_exception()
  File "/home/osboxes/PycharmProjects/microblog/venv/lib/python3.6/site-packages/jinja2/environment.py", line 832, in handle_exception
    reraise(*rewrite_traceback_stack(source=source))
  File "/home/osboxes/PycharmProjects/microblog/venv/lib/python3.6/site-packages/jinja2/_compat.py", line 28, in reraise
    raise value.with_traceback(tb)
  File "/home/osboxes/PycharmProjects/microblog/app/templates/user.html", line 1, in top-level template code
    {% extends "base.html" %}
  File "/home/osboxes/PycharmProjects/microblog/app/templates/base.html", line 30, in top-level template code
    {% block content %}{% endblock %}
  File "/home/osboxes/PycharmProjects/microblog/app/templates/user.html", line 14, in block "content"
    {% elif not current_user.is_fowllowing(user) %}
jinja2.exceptions.UndefinedError: 'app.models.User object' has no attribute 'is_fowllowing'
2020-03-19 05:01:04,895 INFO: Microblog startup [in /home/osboxes/PycharmProjects/microblog/app/__init__.py:43]
2020-03-19 05:04:57,617 INFO: Microblog startup [in /home/osboxes/PycharmProjects/microblog/app/__init__.py:43]
2020-03-19 05:06:52,521 INFO: Microblog startup [in /home/osboxes/PycharmProjects/microblog/app/__init__.py:43]
2020-03-19 05:06:58,373 INFO: Microblog startup [in /home/osboxes/PycharmProjects/microblog/app/__init__.py:43]
2020-03-19 05:08:45,631 INFO: Microblog startup [in /home/osboxes/PycharmProjects/microblog/app/__init__.py:43]
2020-03-19 05:12:37,918 INFO: Microblog startup [in /home/osboxes/PycharmProjects/microblog/app/__init__.py:43]
2020-03-19 05:13:59,833 INFO: Microblog startup [in /home/osboxes/PycharmProjects/microblog/app/__init__.py:43]
2020-03-19 05:14:27,335 INFO: Microblog startup [in /home/osboxes/PycharmProjects/microblog/app/__init__.py:43]
2020-03-19 05:14:40,978 INFO: Microblog startup [in /home/osboxes/PycharmProjects/microblog/app/__init__.py:43]
2020-03-19 05:18:50,570 INFO: Microblog startup [in /home/osboxes/PycharmProjects/microblog/app/__init__.py:43]
2020-03-19 05:20:41,588 INFO: Microblog startup [in /home/osboxes/PycharmProjects/microblog/app/__init__.py:43]
2020-03-19 05:34:41,945 INFO: Microblog startup [in /home/osboxes/PycharmProjects/microblog/app/__init__.py:43]
2020-03-19 05:40:52,445 INFO: Microblog startup [in /home/osboxes/PycharmProjects/microblog/app/__init__.py:43]
2020-03-19 05:40:59,789 INFO: Microblog startup [in /home/osboxes/PycharmProjects/microblog/app/__init__.py:43]
2020-03-19 05:41:05,329 INFO: Microblog startup [in /home/osboxes/PycharmProjects/microblog/app/__init__.py:43]
2020-03-19 05:47:41,427 INFO: Microblog startup [in /home/osboxes/PycharmProjects/microblog/app/__init__.py:43]
2020-03-19 05:53:05,163 INFO: Microblog startup [in /home/osboxes/PycharmProjects/microblog/app/__init__.py:43]
2020-03-19 05:53:49,922 INFO: Microblog startup [in /home/osboxes/PycharmProjects/microblog/app/__init__.py:43]
2020-03-19 05:54:25,797 INFO: Microblog startup [in /home/osboxes/PycharmProjects/microblog/app/__init__.py:43]
2020-03-19 06:10:17,883 INFO: Microblog startup [in /home/osboxes/PycharmProjects/microblog/app/__init__.py:43]
2020-03-19 06:12:54,117 INFO: Microblog startup [in /home/osboxes/PycharmProjects/microblog/app/__init__.py:43]
2020-03-19 06:13:39,613 INFO: Microblog startup [in /home/osboxes/PycharmProjects/microblog/app/__init__.py:43]
2020-03-19 06:13:56,040 INFO: Microblog startup [in /home/osboxes/PycharmProjects/microblog/app/__init__.py:43]
2020-03-20 15:03:39,562 INFO: Microblog startup [in /home/osboxes/PycharmProjects/microblog/app/__init__.py:43]
2020-03-20 15:44:24,988 INFO: Microblog startup [in /home/osboxes/PycharmProjects/microblog/app/__init__.py:43]
2020-03-20 15:44:35,309 ERROR: Exception on / [GET] [in /home/osboxes/PycharmProjects/microblog/venv/lib/python3.6/site-packages/flask/app.py:1891]
Traceback (most recent call last):
  File "/home/osboxes/PycharmProjects/microblog/venv/lib/python3.6/site-packages/flask/app.py", line 2446, in wsgi_app
    response = self.full_dispatch_request()
  File "/home/osboxes/PycharmProjects/microblog/venv/lib/python3.6/site-packages/flask/app.py", line 1951, in full_dispatch_request
    rv = self.handle_user_exception(e)
  File "/home/osboxes/PycharmProjects/microblog/venv/lib/python3.6/site-packages/flask/app.py", line 1820, in handle_user_exception
    reraise(exc_type, exc_value, tb)
  File "/home/osboxes/PycharmProjects/microblog/venv/lib/python3.6/site-packages/flask/_compat.py", line 39, in reraise
    raise value
  File "/home/osboxes/PycharmProjects/microblog/venv/lib/python3.6/site-packages/flask/app.py", line 1949, in full_dispatch_request
    rv = self.dispatch_request()
  File "/home/osboxes/PycharmProjects/microblog/venv/lib/python3.6/site-packages/flask/app.py", line 1935, in dispatch_request
    return self.view_functions[rule.endpoint](**req.view_args)
  File "/home/osboxes/PycharmProjects/microblog/venv/lib/python3.6/site-packages/flask_login/utils.py", line 272, in decorated_view
    return func(*args, **kwargs)
  File "/home/osboxes/PycharmProjects/microblog/app/routes.py", line 29, in index
    posts = current_user.followed_post().paginate(
  File "/home/osboxes/PycharmProjects/microblog/venv/lib/python3.6/site-packages/werkzeug/local.py", line 347, in __getattr__
    return getattr(self._get_current_object(), name)
AttributeError: 'User' object has no attribute 'followed_post'
2020-03-20 15:44:44,123 ERROR: Exception on /index [GET] [in /home/osboxes/PycharmProjects/microblog/venv/lib/python3.6/site-packages/flask/app.py:1891]
Traceback (most recent call last):
  File "/home/osboxes/PycharmProjects/microblog/venv/lib/python3.6/site-packages/flask/app.py", line 2446, in wsgi_app
    response = self.full_dispatch_request()
  File "/home/osboxes/PycharmProjects/microblog/venv/lib/python3.6/site-packages/flask/app.py", line 1951, in full_dispatch_request
    rv = self.handle_user_exception(e)
  File "/home/osboxes/PycharmProjects/microblog/venv/lib/python3.6/site-packages/flask/app.py", line 1820, in handle_user_exception
    reraise(exc_type, exc_value, tb)
  File "/home/osboxes/PycharmProjects/microblog/venv/lib/python3.6/site-packages/flask/_compat.py", line 39, in reraise
    raise value
  File "/home/osboxes/PycharmProjects/microblog/venv/lib/python3.6/site-packages/flask/app.py", line 1949, in full_dispatch_request
    rv = self.dispatch_request()
  File "/home/osboxes/PycharmProjects/microblog/venv/lib/python3.6/site-packages/flask/app.py", line 1935, in dispatch_request
    return self.view_functions[rule.endpoint](**req.view_args)
  File "/home/osboxes/PycharmProjects/microblog/venv/lib/python3.6/site-packages/flask_login/utils.py", line 272, in decorated_view
    return func(*args, **kwargs)
  File "/home/osboxes/PycharmProjects/microblog/app/routes.py", line 29, in index
    posts = current_user.followed_post().paginate(
  File "/home/osboxes/PycharmProjects/microblog/venv/lib/python3.6/site-packages/werkzeug/local.py", line 347, in __getattr__
    return getattr(self._get_current_object(), name)
AttributeError: 'User' object has no attribute 'followed_post'
