2020-05-04 02:28:09,966 INFO: Microblog startup [in C:\Users\s2905\Desktop\EA Project\abc\app\__init__.py:74]
2020-05-04 02:28:18,082 ERROR: Exception on / [GET] [in C:\Users\s2905\Desktop\EA Project\abc\venv\lib\site-packages\flask\app.py:1891]
Traceback (most recent call last):
  File "C:\Users\s2905\Desktop\EA Project\abc\venv\lib\site-packages\flask\app.py", line 2447, in wsgi_app
    response = self.full_dispatch_request()
  File "C:\Users\s2905\Desktop\EA Project\abc\venv\lib\site-packages\flask\app.py", line 1952, in full_dispatch_request
    rv = self.handle_user_exception(e)
  File "C:\Users\s2905\Desktop\EA Project\abc\venv\lib\site-packages\flask\app.py", line 1821, in handle_user_exception
    reraise(exc_type, exc_value, tb)
  File "C:\Users\s2905\Desktop\EA Project\abc\venv\lib\site-packages\flask\_compat.py", line 39, in reraise
    raise value
  File "C:\Users\s2905\Desktop\EA Project\abc\venv\lib\site-packages\flask\app.py", line 1950, in full_dispatch_request
    rv = self.dispatch_request()
  File "C:\Users\s2905\Desktop\EA Project\abc\venv\lib\site-packages\flask\app.py", line 1936, in dispatch_request
    return self.view_functions[rule.endpoint](**req.view_args)
  File "C:\Users\s2905\Desktop\EA Project\abc\venv\lib\site-packages\flask_login\utils.py", line 272, in decorated_view
    return func(*args, **kwargs)
  File "C:\Users\s2905\Desktop\EA Project\abc\app\main\routes.py", line 25, in ez
    name = test.email
AttributeError: 'list' object has no attribute 'email'
2020-05-04 02:35:13,076 INFO: Microblog startup [in C:\Users\s2905\Desktop\EA Project\abc\app\__init__.py:74]
2020-05-04 02:35:18,675 ERROR: Exception on / [GET] [in C:\Users\s2905\Desktop\EA Project\abc\venv\lib\site-packages\flask\app.py:1891]
Traceback (most recent call last):
  File "C:\Users\s2905\Desktop\EA Project\abc\venv\lib\site-packages\flask\app.py", line 2447, in wsgi_app
    response = self.full_dispatch_request()
  File "C:\Users\s2905\Desktop\EA Project\abc\venv\lib\site-packages\flask\app.py", line 1952, in full_dispatch_request
    rv = self.handle_user_exception(e)
  File "C:\Users\s2905\Desktop\EA Project\abc\venv\lib\site-packages\flask\app.py", line 1821, in handle_user_exception
    reraise(exc_type, exc_value, tb)
  File "C:\Users\s2905\Desktop\EA Project\abc\venv\lib\site-packages\flask\_compat.py", line 39, in reraise
    raise value
  File "C:\Users\s2905\Desktop\EA Project\abc\venv\lib\site-packages\flask\app.py", line 1950, in full_dispatch_request
    rv = self.dispatch_request()
  File "C:\Users\s2905\Desktop\EA Project\abc\venv\lib\site-packages\flask\app.py", line 1936, in dispatch_request
    return self.view_functions[rule.endpoint](**req.view_args)
  File "C:\Users\s2905\Desktop\EA Project\abc\venv\lib\site-packages\flask_login\utils.py", line 272, in decorated_view
    return func(*args, **kwargs)
  File "C:\Users\s2905\Desktop\EA Project\abc\app\main\routes.py", line 24, in ez
    body = News.query.get(content)
NameError: name 'content' is not defined
2020-05-04 02:36:00,495 INFO: Microblog startup [in C:\Users\s2905\Desktop\EA Project\abc\app\__init__.py:74]
2020-05-04 02:52:02,457 INFO: Microblog startup [in C:\Users\s2905\Desktop\EA Project\abc\app\__init__.py:74]
2020-05-04 03:03:05,296 INFO: Microblog startup [in C:\Users\s2905\Desktop\EA Project\abc\app\__init__.py:74]
2020-05-04 03:03:10,950 ERROR: Exception on / [GET] [in C:\Users\s2905\Desktop\EA Project\abc\venv\lib\site-packages\flask\app.py:1891]
Traceback (most recent call last):
  File "C:\Users\s2905\Desktop\EA Project\abc\venv\lib\site-packages\flask\app.py", line 2447, in wsgi_app
    response = self.full_dispatch_request()
  File "C:\Users\s2905\Desktop\EA Project\abc\venv\lib\site-packages\flask\app.py", line 1952, in full_dispatch_request
    rv = self.handle_user_exception(e)
  File "C:\Users\s2905\Desktop\EA Project\abc\venv\lib\site-packages\flask\app.py", line 1821, in handle_user_exception
    reraise(exc_type, exc_value, tb)
  File "C:\Users\s2905\Desktop\EA Project\abc\venv\lib\site-packages\flask\_compat.py", line 39, in reraise
    raise value
  File "C:\Users\s2905\Desktop\EA Project\abc\venv\lib\site-packages\flask\app.py", line 1950, in full_dispatch_request
    rv = self.dispatch_request()
  File "C:\Users\s2905\Desktop\EA Project\abc\venv\lib\site-packages\flask\app.py", line 1936, in dispatch_request
    return self.view_functions[rule.endpoint](**req.view_args)
  File "C:\Users\s2905\Desktop\EA Project\abc\venv\lib\site-packages\flask_login\utils.py", line 272, in decorated_view
    return func(*args, **kwargs)
  File "C:\Users\s2905\Desktop\EA Project\abc\app\main\routes.py", line 23, in ez
    all = News(name=News.title, body=News.content)
  File "<string>", line 4, in __init__
  File "C:\Users\s2905\Desktop\EA Project\abc\venv\lib\site-packages\sqlalchemy\orm\state.py", line 433, in _initialize_instance
    manager.dispatch.init_failure(self, args, kwargs)
  File "C:\Users\s2905\Desktop\EA Project\abc\venv\lib\site-packages\sqlalchemy\util\langhelpers.py", line 68, in __exit__
    compat.raise_(
  File "C:\Users\s2905\Desktop\EA Project\abc\venv\lib\site-packages\sqlalchemy\util\compat.py", line 178, in raise_
    raise exception
  File "C:\Users\s2905\Desktop\EA Project\abc\venv\lib\site-packages\sqlalchemy\orm\state.py", line 430, in _initialize_instance
    return manager.original_init(*mixed[1:], **kwargs)
  File "C:\Users\s2905\Desktop\EA Project\abc\venv\lib\site-packages\sqlalchemy\ext\declarative\base.py", line 839, in _declarative_constructor
    raise TypeError(
TypeError: 'name' is an invalid keyword argument for News
2020-05-04 03:04:25,311 INFO: Microblog startup [in C:\Users\s2905\Desktop\EA Project\abc\app\__init__.py:74]
2020-05-04 03:05:47,262 INFO: Microblog startup [in C:\Users\s2905\Desktop\EA Project\abc\app\__init__.py:74]
2020-05-04 03:06:04,260 INFO: Microblog startup [in C:\Users\s2905\Desktop\EA Project\abc\app\__init__.py:74]
2020-05-04 03:08:46,176 INFO: Microblog startup [in C:\Users\s2905\Desktop\EA Project\abc\app\__init__.py:74]
2020-05-04 03:12:22,785 INFO: Microblog startup [in C:\Users\s2905\Desktop\EA Project\abc\app\__init__.py:74]
2020-05-04 03:12:27,427 ERROR: Exception on / [GET] [in C:\Users\s2905\Desktop\EA Project\abc\venv\lib\site-packages\flask\app.py:1891]
Traceback (most recent call last):
  File "C:\Users\s2905\Desktop\EA Project\abc\venv\lib\site-packages\flask\app.py", line 2447, in wsgi_app
    response = self.full_dispatch_request()
  File "C:\Users\s2905\Desktop\EA Project\abc\venv\lib\site-packages\flask\app.py", line 1952, in full_dispatch_request
    rv = self.handle_user_exception(e)
  File "C:\Users\s2905\Desktop\EA Project\abc\venv\lib\site-packages\flask\app.py", line 1821, in handle_user_exception
    reraise(exc_type, exc_value, tb)
  File "C:\Users\s2905\Desktop\EA Project\abc\venv\lib\site-packages\flask\_compat.py", line 39, in reraise
    raise value
  File "C:\Users\s2905\Desktop\EA Project\abc\venv\lib\site-packages\flask\app.py", line 1950, in full_dispatch_request
    rv = self.dispatch_request()
  File "C:\Users\s2905\Desktop\EA Project\abc\venv\lib\site-packages\flask\app.py", line 1936, in dispatch_request
    return self.view_functions[rule.endpoint](**req.view_args)
  File "C:\Users\s2905\Desktop\EA Project\abc\venv\lib\site-packages\flask_login\utils.py", line 272, in decorated_view
    return func(*args, **kwargs)
  File "C:\Users\s2905\Desktop\EA Project\abc\app\main\routes.py", line 23, in ez
    all = News(title=News.query.all(), content=News.body(News.query.all()))
  File "C:\Users\s2905\Desktop\EA Project\abc\app\models.py", line 103, in body
    return News.query.get(self.content)
AttributeError: 'list' object has no attribute 'content'
2020-05-04 03:16:48,861 INFO: Microblog startup [in C:\Users\s2905\Desktop\EA Project\abc\app\__init__.py:74]
2020-05-04 03:25:18,030 INFO: Microblog startup [in C:\Users\s2905\Desktop\EA Project\abc\app\__init__.py:74]
2020-05-04 03:25:22,667 ERROR: Exception on / [GET] [in C:\Users\s2905\Desktop\EA Project\abc\venv\lib\site-packages\flask\app.py:1891]
Traceback (most recent call last):
  File "C:\Users\s2905\Desktop\EA Project\abc\venv\lib\site-packages\flask\app.py", line 2447, in wsgi_app
    response = self.full_dispatch_request()
  File "C:\Users\s2905\Desktop\EA Project\abc\venv\lib\site-packages\flask\app.py", line 1952, in full_dispatch_request
    rv = self.handle_user_exception(e)
  File "C:\Users\s2905\Desktop\EA Project\abc\venv\lib\site-packages\flask\app.py", line 1821, in handle_user_exception
    reraise(exc_type, exc_value, tb)
  File "C:\Users\s2905\Desktop\EA Project\abc\venv\lib\site-packages\flask\_compat.py", line 39, in reraise
    raise value
  File "C:\Users\s2905\Desktop\EA Project\abc\venv\lib\site-packages\flask\app.py", line 1950, in full_dispatch_request
    rv = self.dispatch_request()
  File "C:\Users\s2905\Desktop\EA Project\abc\venv\lib\site-packages\flask\app.py", line 1936, in dispatch_request
    return self.view_functions[rule.endpoint](**req.view_args)
  File "C:\Users\s2905\Desktop\EA Project\abc\venv\lib\site-packages\flask_login\utils.py", line 272, in decorated_view
    return func(*args, **kwargs)
  File "C:\Users\s2905\Desktop\EA Project\abc\app\main\routes.py", line 23, in ez
    all = News.query.all('title')
TypeError: all() takes 1 positional argument but 2 were given
2020-05-04 03:25:51,274 INFO: Microblog startup [in C:\Users\s2905\Desktop\EA Project\abc\app\__init__.py:74]
